Workbook

Sheet instruments
A1: row_id | B1: name | C1: identifier | D1: policy_area_ceps | E1: ceps_table_status | F1: proposal_date | G1: confidence_proposal_date | H1: adoption_date | I1: oj_publication_date | J1: entry_into_force | K1: status_ceps_jul2025 | L1: status_oct2026 | M1: celex_measured | N1: text_measured | O1: source_url | P1: pages | Q1: words_legal_text | R1: words_preamble | S1: words_recitals | T1: words_articles | U1: words_annexes | V1: words_memorandum | W1: words_financial_statement | X1: restrictions_total | Y1: r_obligation | Z1: r_prohibition | AA1: r_restricted_permission | AB1: r_explicit_requirement | AC1: r_duty_of_result | AD1: addr_private_parties | AE1: addr_member_states | AF1: addr_eu_institutions | AG1: addr_unclear | AH1: consolidated_celex | AI1: consolidated_restrictions_total | AJ1: consolidated_addr_private_parties | AK1: n_implementing_acts | AL1: n_delegated_acts | AM1: n_other_commission_council_acts | AN1: n_guidance_eurlex | AO1: n_guidance_web | AP1: n_guidance_edpb | AQ1: n_guidance_eba | AR1: n_guidance_esma | AS1: restrictions_in_implementing_and_delegated_acts | AT1: national_transposition_measures | AU1: member_states_with_measures | AV1: n_amending_acts | AW1: first_amendment_date | AX1: latest_amendment_date | AY1: n_corrigenda | AZ1: proposal_celex | BA1: proposal_text_source | BB1: proposal_words_legal_text | BC1: proposal_restrictions_total | BD1: proposal_addr_private_parties | BE1: change_words | BF1: change_words_pct | BG1: change_restrictions | BH1: change_restrictions_pct | BI1: change_restrictions_private | BJ1: note
A2: 1 | B2: Frequency Bands Directive (GSM) | C2: Directive 87/372/EEC | D2: Connectivity | E2: enacted | F2: 1986-09-01 | G2: low | H2: 1987-06-25 | I2: 1987-06-25 | J2: 1987-06-30 | K2: adopted | L2: adopted | M2: 31987L0372 | N2: Original act as published in the OJ | O2: https://eur-lex.europa.eu/legal-content/EN/TXT/?uri=CELEX:31987L0372 | P2: 2 | Q2: 866 | R2: 618 | S2: 483 | T2: 248 | U2: 0 | V2: 0 | W2: 0 | X2: 6 | Y2: 4 | Z2: 0 | AA2: 0 | AB2: 0 | AC2: 2 | AD2: 0 | AE2: 5 | AF2: 1 | AG2: 0 | AH2: 01987L0372-19870630 | AI2: 0 | AJ2: 0 | AK2: =COUNTIFS(secondary_acts!$A$2:$A$771,$A2,secondary_acts!$E$2:$E$771,"implementing") -> 0 | AL2: =COUNTIFS(secondary_acts!$A$2:$A$771,$A2,secondary_acts!$E$2:$E$771,"delegated") -> 0 | AM2: =COUNTIFS(secondary_acts!$A$2:$A$771,$A2,secondary_acts!$E$2:$E$771,"other Commission/Council act") -> 0 | AN2: =COUNTIFS(secondary_acts!$A$2:$A$771,$A2,secondary_acts!$E$2:$E$771,"guidance") -> 0 | AO2: =COUNTIF(guidance_web!$A$2:$A$7,$A2) -> 0 | AP2: =COUNTIFS(guidance_agencies!$A$2:$A$81,$A2,guidance_agencies!$D$2:$D$81,"EDPB") -> 0 | AQ2: =COUNTIFS(guidance_agencies!$A$2:$A$81,$A2,guidance_agencies!$D$2:$D$81,"EBA") -> 0 | AR2: =COUNTIFS(guidance_agencies!$A$2:$A$81,$A2,guidance_agencies!$D$2:$D$81,"ESMA") -> 0 | AS2: =SUMIFS(secondary_acts!$S$2:$S$771,secondary_acts!$A$2:$A$771,$A2,secondary_acts!$E$2:$E$771,"implementing")+SUMIFS(secondary_acts!$S$2:$S$771,secondary_acts!$A$2:$A$771,$A2,secondary_acts!$E$2:$E$771,"delegated") -> 0 | AT2: 207 | AU2: 24 | AV2: 1 | AW2: 2009-09-16 | AX2: 2009-09-16 | AY2: 2 | AZ2: 51987PC0035(02) | BA2: PDF text (approximate) | BB2: 841 | BC2: 5 | BD2: 0 | BE2: =IF(ISNUMBER(BB2),Q2-BB2,"") -> 25 | BF2: =IF(AND(ISNUMBER(BB2),BB2>0),(Q2-BB2)/BB2,"") -> 0.029726516 | BG2: =IF(ISNUMBER(BC2),X2-BC2,"") -> 1 | BH2: =IF(AND(ISNUMBER(BC2),BC2>0),(X2-BC2)/BC2,"") -> 0.2 | BI2: =IF(ISNUMBER(BD2),AD2-BD2,"") -> 0
A3: 2 | B3: Unfair Contract Terms Directive | C3: Directive 93/13/EEC | D3: E-commerce & Consumer Protection | E3: enacted | F3: 1990-07-24 | G3: medium | H3: 1993-04-05 | I3: 1993-04-21 | J3: 1993-04-16 | K3: adopted | L3: adopted | M3: 31993L0013 | N3: Original act as published in the OJ | O3: https://eur-lex.europa.eu/legal-content/EN/TXT/?uri=CELEX:31993L0013 | P3: 6 | Q3: 3320 | R3: 1402 | S3: 1323 | T3: 1008 | U3: 910 | V3: 0 | W3: 0 | X3: 26 | Y3: 20 | Z3: 2 | AA3: 0 | AB3: 3 | AC3: 1 | AD3: 6 | AE3: 11 | AF3: 1 | AG3: 8 | AH3: 01993L0013-20220528 | AI3: 39 | AJ3: 6 | AK3: =COUNTIFS(secondary_acts!$A$2:$A$771,$A3,secondary_acts!$E$2:$E$771,"implementing") -> 0 | AL3: =COUNTIFS(secondary_acts!$A$2:$A$771,$A3,secondary_acts!$E$2:$E$771,"delegated") -> 0 | AM3: =COUNTIFS(secondary_acts!$A$2:$A$771,$A3,secondary_acts!$E$2:$E$771,"other Commission/Council act") -> 0 | AN3: =COUNTIFS(secondary_acts!$A$2:$A$771,$A3,secondary_acts!$E$2:$E$771,"guidance") -> 1 | AO3: =COUNTIF(guidance_web!$A$2:$A$7,$A3) -> 0 | AP3: =COUNTIFS(guidance_agencies!$A$2:$A$81,$A3,guidance_agencies!$D$2:$D$81,"EDPB") -> 0 | AQ3: =COUNTIFS(guidance_agencies!$A$2:$A$81,$A3,guidance_agencies!$D$2:$D$81,"EBA") -> 0 | AR3: =COUNTIFS(guidance_agencies!$A$2:$A$81,$A3,guidance_agencies!$D$2:$D$81,"ESMA") -> 0 | AS3: =SUMIFS(secondary_acts!$S$2:$S$771,secondary_acts!$A$2:$A$771,$A3,secondary_acts!$E$2:$E$771,"implementing")+SUMIFS(secondary_acts!$S$2:$S$771,secondary_acts!$A$2:$A$771,$A3,secondary_acts!$E$2:$E$771,"delegated") -> 0 | AT3: 1342 | AU3: 25 | AV3: 2 | AW3: 2011-10-25 | AX3: 2019-11-27 | AY3: 13 | AZ3: 51990PC0322 | BA3: PDF text (approximate) | BB3: 2059 | BC3: 11 | BD3: 0 | BE3: =IF(ISNUMBER(BB3),Q3-BB3,"") -> 1261 | BF3: =IF(AND(ISNUMBER(BB3),BB3>0),(Q3-BB3)/BB3,"") -> 0.61243322 | BG3: =IF(ISNUMBER(BC3),X3-BC3,"") -> 15 | BH3: =IF(AND(ISNUMBER(BC3),BC3>0),(X3-BC3)/BC3,"") -> 1.3636364 | BI3: =IF(ISNUMBER(BD3),AD3-BD3,"") -> 6
A4: 3 | B4: Satellite and Cable Directive | C4: Directive 93/83/EEC | D4: Media | E4: enacted | F4: 1991-09-11 | G4: medium | H4: 1993-09-27 | I4: 1993-10-06 | J4: 1993-10-04 | K4: adopted | L4: adopted | M4: 31993L0083 | N4: Original act as published in the OJ | O4: https://eur-lex.europa.eu/legal-content/EN/TXT/?uri=CELEX:31993L0083 | P4: 7 | Q4: 4550 | R4: 2545 | S4: 2449 | T4: 2005 | U4: 0 | V4: 0 | W4: 0 | X4: 35 | Y4: 27 | Z4: 1 | AA4: 1 | AB4: 0 | AC4: 6 | AD4: 4 | AE4: 18 | AF4: 2 | AG4: 11 | AH4: 01993L0083-19931004 | AI4: 35 | AJ4: 4 | AK4: =COUNTIFS(secondary_acts!$A$2:$A$771,$A4,secondary_acts!$E$2:$E$771,"implementing") -> 0 | AL4: =COUNTIFS(secondary_acts!$A$2:$A$771,$A4,secondary_acts!$E$2:$E$771,"delegated") -> 0 | AM4: =COUNTIFS(secondary_acts!$A$2:$A$771,$A4,secondary_acts!$E$2:$E$771,"other Commission/Council act") -> 0 | AN4: =COUNTIFS(secondary_acts!$A$2:$A$771,$A4,secondary_acts!$E$2:$E$771,"guidance") -> 0 | AO4: =COUNTIF(guidance_web!$A$2:$A$7,$A4) -> 0 | AP4: =COUNTIFS(guidance_agencies!$A$2:$A$81,$A4,guidance_agencies!$D$2:$D$81,"EDPB") -> 0 | AQ4: =COUNTIFS(guidance_agencies!$A$2:$A$81,$A4,guidance_agencies!$D$2:$D$81,"EBA") -> 0 | AR4: =COUNTIFS(guidance_agencies!$A$2:$A$81,$A4,guidance_agencies!$D$2:$D$81,"ESMA") -> 0 | AS4: =SUMIFS(secondary_acts!$S$2:$S$771,secondary_acts!$A$2:$A$771,$A4,secondary_acts!$E$2:$E$771,"implementing")+SUMIFS(secondary_acts!$S$2:$S$771,secondary_acts!$A$2:$A$771,$A4,secondary_acts!$E$2:$E$771,"delegated") -> 0 | AT4: 207 | AU4: 23 | AV4: 1 | AW4: 2019-04-17 | AX4: 2019-04-17 | AY4: 1 | AZ4: 51991PC0276 | BA4: PDF text (approximate) | BB4: 3122 | BC4: 30 | BD4: 0 | BE4: =IF(ISNUMBER(BB4),Q4-BB4,"") -> 1428 | BF4: =IF(AND(ISNUMBER(BB4),BB4>0),(Q4-BB4)/BB4,"") -> 0.4573991 | BG4: =IF(ISNUMBER(BC4),X4-BC4,"") -> 5 | BH4: =IF(AND(ISNUMBER(BC4),BC4>0),(X4-BC4)/BC4,"") -> 0.16666667 | BI4: =IF(ISNUMBER(BD4),AD4-BD4,"") -> 4 | BJ4: no consolidated text with amendments in EUR-Lex; consolidated count = original
A5: 4 | B5: Database Directive | C5: Directive 96/9/EC | D5: IPR | E5: enacted | F5: 1992-05-13 | G5: medium | H5: 1996-03-11 | I5: 1996-03-27 | J5: 1996-04-16 | K5: adopted | L5: adopted | M5: 31996L0009 | N5: Original act as published in the OJ | O5: https://eur-lex.europa.eu/legal-content/EN/TXT/?uri=CELEX:31996L0009 | P5: 9 | Q5: 5494 | R5: 3257 | S5: 3156 | T5: 2237 | U5: 0 | V5: 0 | W5: 0 | X5: 33 | Y5: 24 | Z5: 9 | AA5: 0 | AB5: 0 | AC5: 0 | AD5: 8 | AE5: 10 | AF5: 2 | AG5: 13 | AH5: 01996L0009-20190606 | AI5: 33 | AJ5: 8 | AK5: =COUNTIFS(secondary_acts!$A$2:$A$771,$A5,secondary_acts!$E$2:$E$771,"implementing") -> 0 | AL5: =COUNTIFS(secondary_acts!$A$2:$A$771,$A5,secondary_acts!$E$2:$E$771,"delegated") -> 0 | AM5: =COUNTIFS(secondary_acts!$A$2:$A$771,$A5,secondary_acts!$E$2:$E$771,"other Commission/Council act") -> 0 | AN5: =COUNTIFS(secondary_acts!$A$2:$A$771,$A5,secondary_acts!$E$2:$E$771,"guidance") -> 0 | AO5: =COUNTIF(guidance_web!$A$2:$A$7,$A5) -> 0 | AP5: =COUNTIFS(guidance_agencies!$A$2:$A$81,$A5,guidance_agencies!$D$2:$D$81,"EDPB") -> 0 | AQ5: =COUNTIFS(guidance_agencies!$A$2:$A$81,$A5,guidance_agencies!$D$2:$D$81,"EBA") -> 0 | AR5: =COUNTIFS(guidance_agencies!$A$2:$A$81,$A5,guidance_agencies!$D$2:$D$81,"ESMA") -> 0 | AS5: =SUMIFS(secondary_acts!$S$2:$S$771,secondary_acts!$A$2:$A$771,$A5,secondary_acts!$E$2:$E$771,"implementing")+SUMIFS(secondary_acts!$S$2:$S$771,secondary_acts!$A$2:$A$771,$A5,secondary_acts!$E$2:$E$771,"delegated") -> 0 | AT5: 1049 | AU5: 22 | AV5: 1 | AW5: 2019-04-17 | AX5: 2019-04-17 | AY5: 1 | AZ5: 51992PC0024 | BA5: PDF text (approximate) | BB5: 4314 | BC5: 28 | BD5: 2 | BE5: =IF(ISNUMBER(BB5),Q5-BB5,"") -> 1180 | BF5: =IF(AND(ISNUMBER(BB5),BB5>0),(Q5-BB5)/BB5,"") -> 0.27352805 | BG5: =IF(ISNUMBER(BC5),X5-BC5,"") -> 5 | BH5: =IF(AND(ISNUMBER(BC5),BC5>0),(X5-BC5)/BC5,"") -> 0.17857143 | BI5: =IF(ISNUMBER(BD5),AD5-BD5,"") -> 6
A6: 5 | B6: Community Design Regulation | C6: Regulation (EC) 6/2002 | D6: IPR | E6: enacted | F6: 1993-12-03 | G6: medium | H6: 2001-12-12 | I6: 2002-01-09 | J6: 2002-03-06 | K6: adopted | L6: adopted | M6: 32002R0006 | N6: Original act as published in the OJ | O6: https://eur-lex.europa.eu/legal-content/EN/TXT/?uri=CELEX:32002R0006 | P6: 24 | Q6: 17870 | R6: 2070 | S6: 1978 | T6: 15800 | U6: 0 | V6: 0 | W6: 0 | X6: 280 | Y6: 241 | Z6: 31 | AA6: 7 | AB6: 1 | AC6: 0 | AD6: 29 | AE6: 50 | AF6: 65 | AG6: 136 | AH6: 02002R0006-20260701 | AI6: 481 | AJ6: 51 | AK6: =COUNTIFS(secondary_acts!$A$2:$A$771,$A6,secondary_acts!$E$2:$E$771,"implementing") -> 2 | AL6: =COUNTIFS(secondary_acts!$A$2:$A$771,$A6,secondary_acts!$E$2:$E$771,"delegated") -> 1 | AM6: =COUNTIFS(secondary_acts!$A$2:$A$771,$A6,secondary_acts!$E$2:$E$771,"other Commission/Council act") -> 4 | AN6: =COUNTIFS(secondary_acts!$A$2:$A$771,$A6,secondary_acts!$E$2:$E$771,"guidance") -> 0 | AO6: =COUNTIF(guidance_web!$A$2:$A$7,$A6) -> 0 | AP6: =COUNTIFS(guidance_agencies!$A$2:$A$81,$A6,guidance_agencies!$D$2:$D$81,"EDPB") -> 0 | AQ6: =COUNTIFS(guidance_agencies!$A$2:$A$81,$A6,guidance_agencies!$D$2:$D$81,"EBA") -> 0 | AR6: =COUNTIFS(guidance_agencies!$A$2:$A$81,$A6,guidance_agencies!$D$2:$D$81,"ESMA") -> 0 | AS6: =SUMIFS(secondary_acts!$S$2:$S$771,secondary_acts!$A$2:$A$771,$A6,secondary_acts!$E$2:$E$771,"implementing")+SUMIFS(secondary_acts!$S$2:$S$771,secondary_acts!$A$2:$A$771,$A6,secondary_acts!$E$2:$E$771,"delegated") -> 143 | AV6: 2 | AW6: 2006-12-18 | AX6: 2024-10-23 | AY6: 20 | AZ6: 51993PC0342 | BA6: not comparable: 1993 proposal PDF bundles the companion Design Directive proposal | BE6: =IF(ISNUMBER(BB6),Q6-BB6,"") | BF6: =IF(AND(ISNUMBER(BB6),BB6>0),(Q6-BB6)/BB6,"") | BG6: =IF(ISNUMBER(BC6),X6-BC6,"") | BH6: =IF(AND(ISNUMBER(BC6),BC6>0),(X6-BC6)/BC6,"") | BI6: =IF(ISNUMBER(BD6),AD6-BD6,"")
A7: 6 | B7: Price Indication Directive | C7: Directive 98/6/EC | D7: E-commerce & Consumer Protection | E7: enacted | F7: 1995-07-24 | G7: low | H7: 1998-02-16 | I7: 1998-03-25 | J7: 1998-03-18 | K7: adopted | L7: adopted | M7: 31998L0006 | N7: Original act as published in the OJ | O7: https://eur-lex.europa.eu/legal-content/EN/TXT/?uri=CELEX:31998L0006 | P7: 5 | Q7: 1901 | R7: 853 | S7: 731 | T7: 1048 | U7: 0 | V7: 0 | W7: 0 | X7: 23 | Y7: 22 | Z7: 1 | AA7: 0 | AB7: 0 | AC7: 0 | AD7: 1 | AE7: 10 | AF7: 3 | AG7: 9 | AH7: 01998L0006-20220528 | AI7: 27 | AJ7: 0 | AK7: =COUNTIFS(secondary_acts!$A$2:$A$771,$A7,secondary_acts!$E$2:$E$771,"implementing") -> 0 | AL7: =COUNTIFS(secondary_acts!$A$2:$A$771,$A7,secondary_acts!$E$2:$E$771,"delegated") -> 0 | AM7: =COUNTIFS(secondary_acts!$A$2:$A$771,$A7,secondary_acts!$E$2:$E$771,"other Commission/Council act") -> 0 | AN7: =COUNTIFS(secondary_acts!$A$2:$A$771,$A7,secondary_acts!$E$2:$E$771,"guidance") -> 1 | AO7: =COUNTIF(guidance_web!$A$2:$A$7,$A7) -> 0 | AP7: =COUNTIFS(guidance_agencies!$A$2:$A$81,$A7,guidance_agencies!$D$2:$D$81,"EDPB") -> 0 | AQ7: =COUNTIFS(guidance_agencies!$A$2:$A$81,$A7,guidance_agencies!$D$2:$D$81,"EBA") -> 0 | AR7: =COUNTIFS(guidance_agencies!$A$2:$A$81,$A7,guidance_agencies!$D$2:$D$81,"ESMA") -> 0 | AS7: =SUMIFS(secondary_acts!$S$2:$S$771,secondary_acts!$A$2:$A$771,$A7,secondary_acts!$E$2:$E$771,"implementing")+SUMIFS(secondary_acts!$S$2:$S$771,secondary_acts!$A$2:$A$771,$A7,secondary_acts!$E$2:$E$771,"delegated") -> 0 | AT7: 359 | AU7: 26 | AV7: 1 | AW7: 2019-11-27 | AX7: 2019-11-27 | AY7: 1 | AZ7: 51995PC0276 | BA7: EUR-Lex HTML | BB7: 1809 | BC7: 21 | BD7: 0 | BE7: =IF(ISNUMBER(BB7),Q7-BB7,"") -> 92 | BF7: =IF(AND(ISNUMBER(BB7),BB7>0),(Q7-BB7)/BB7,"") -> 0.050856827 | BG7: =IF(ISNUMBER(BC7),X7-BC7,"") -> 2 | BH7: =IF(AND(ISNUMBER(BC7),BC7>0),(X7-BC7)/BC7,"") -> 0.095238095 | BI7: =IF(ISNUMBER(BD7),AD7-BD7,"") -> 1
A8: 7 | B8: Information Society (InfoSoc) Directive | C8: Directive 2001/29/EC | D8: Media | E8: enacted | F8: 1997-12-10 | G8: high | H8: 2001-05-22 | I8: 2001-06-25 | J8: 2001-06-22 | K8: adopted | L8: adopted | M8: 32001L0029 | N8: Original act as published in the OJ | O8: https://eur-lex.europa.eu/legal-content/EN/TXT/?uri=CELEX:32001L0029 | P8: 10 | Q8: 8127 | R8: 4811 | S8: 4670 | T8: 3316 | U8: 0 | V8: 0 | W8: 0 | X8: 35 | Y8: 29 | Z8: 3 | AA8: 2 | AB8: 0 | AC8: 1 | AD8: 0 | AE8: 21 | AF8: 3 | AG8: 11 | AH8: 02001L0029-20190606 | AI8: 35 | AJ8: 0 | AK8: =COUNTIFS(secondary_acts!$A$2:$A$771,$A8,secondary_acts!$E$2:$E$771,"implementing") -> 0 | AL8: =COUNTIFS(secondary_acts!$A$2:$A$771,$A8,secondary_acts!$E$2:$E$771,"delegated") -> 0 | AM8: =COUNTIFS(secondary_acts!$A$2:$A$771,$A8,secondary_acts!$E$2:$E$771,"other Commission/Council act") -> 0 | AN8: =COUNTIFS(secondary_acts!$A$2:$A$771,$A8,secondary_acts!$E$2:$E$771,"guidance") -> 0 | AO8: =COUNTIF(guidance_web!$A$2:$A$7,$A8) -> 0 | AP8: =COUNTIFS(guidance_agencies!$A$2:$A$81,$A8,guidance_agencies!$D$2:$D$81,"EDPB") -> 0 | AQ8: =COUNTIFS(guidance_agencies!$A$2:$A$81,$A8,guidance_agencies!$D$2:$D$81,"EBA") -> 0 | AR8: =COUNTIFS(guidance_agencies!$A$2:$A$81,$A8,guidance_agencies!$D$2:$D$81,"ESMA") -> 0 | AS8: =SUMIFS(secondary_acts!$S$2:$S$771,secondary_acts!$A$2:$A$771,$A8,secondary_acts!$E$2:$E$771,"implementing")+SUMIFS(secondary_acts!$S$2:$S$771,secondary_acts!$A$2:$A$771,$A8,secondary_acts!$E$2:$E$771,"delegated") -> 0 | AT8: 1103 | AU8: 28 | AV8: 2 | AW8: 2017-09-13 | AX8: 2019-04-17 | AY8: 8 | AZ8: 51997PC0628 | BA8: EUR-Lex HTML | BB8: 5152 | BC8: 27 | BD8: 0 | BE8: =IF(ISNUMBER(BB8),Q8-BB8,"") -> 2975 | BF8: =IF(AND(ISNUMBER(BB8),BB8>0),(Q8-BB8)/BB8,"") -> 0.57744565 | BG8: =IF(ISNUMBER(BC8),X8-BC8,"") -> 8 | BH8: =IF(AND(ISNUMBER(BC8),BC8>0),(X8-BC8)/BC8,"") -> 0.2962963 | BI8: =IF(ISNUMBER(BD8),AD8-BD8,"") -> 0
A9: 8 | B9: E-commerce Directive | C9: Directive 2000/31/EC | D9: E-commerce & Consumer Protection | E9: enacted | F9: 1998-11-18 | G9: high | H9: 2000-06-08 | I9: 2000-06-08 | J9: 2000-07-17 | K9: adopted | L9: adopted | M9: 32000L0031 | N9: Original act as published in the OJ | O9: https://eur-lex.europa.eu/legal-content/EN/TXT/?uri=CELEX:32000L0031 | P9: 16 | Q9: 10148 | R9: 5471 | S9: 5320 | T9: 4370 | U9: 307 | V9: 0 | W9: 0 | X9: 72 | Y9: 50 | Z9: 3 | AA9: 0 | AB9: 2 | AC9: 17 | AD9: 6 | AE9: 42 | AF9: 9 | AG9: 15 | AH9: 02000L0031-20240217 | AI9: 68 | AJ9: 6 | AK9: =COUNTIFS(secondary_acts!$A$2:$A$771,$A9,secondary_acts!$E$2:$E$771,"implementing") -> 0 | AL9: =COUNTIFS(secondary_acts!$A$2:$A$771,$A9,secondary_acts!$E$2:$E$771,"delegated") -> 0 | AM9: =COUNTIFS(secondary_acts!$A$2:$A$771,$A9,secondary_acts!$E$2:$E$771,"other Commission/Council act") -> 0 | AN9: =COUNTIFS(secondary_acts!$A$2:$A$771,$A9,secondary_acts!$E$2:$E$771,"guidance") -> 0 | AO9: =COUNTIF(guidance_web!$A$2:$A$7,$A9) -> 0 | AP9: =COUNTIFS(guidance_agencies!$A$2:$A$81,$A9,guidance_agencies!$D$2:$D$81,"EDPB") -> 0 | AQ9: =COUNTIFS(guidance_agencies!$A$2:$A$81,$A9,guidance_agencies!$D$2:$D$81,"EBA") -> 0 | AR9: =COUNTIFS(guidance_agencies!$A$2:$A$81,$A9,guidance_agencies!$D$2:$D$81,"ESMA") -> 0 | AS9: =SUMIFS(secondary_acts!$S$2:$S$771,secondary_acts!$A$2:$A$771,$A9,secondary_acts!$E$2:$E$771,"implementing")+SUMIFS(secondary_acts!$S$2:$S$771,secondary_acts!$A$2:$A$771,$A9,secondary_acts!$E$2:$E$771,"delegated") -> 0 | AT9: 2522 | AU9: 27 | AV9: 1 | AW9: 2022-10-19 | AX9: 2022-10-19 | AY9: 4 | AZ9: 51998PC0586 | BA9: EUR-Lex HTML | BB9: 7063 | BC9: 78 | BD9: 7 | BE9: =IF(ISNUMBER(BB9),Q9-BB9,"") -> 3085 | BF9: =IF(AND(ISNUMBER(BB9),BB9>0),(Q9-BB9)/BB9,"") -> 0.43678324 | BG9: =IF(ISNUMBER(BC9),X9-BC9,"") -> -6 | BH9: =IF(AND(ISNUMBER(BC9),BC9>0),(X9-BC9)/BC9,"") -> -0.076923077 | BI9: =IF(ISNUMBER(BD9),AD9-BD9,"") -> -1
A10: 9 | B10: ePrivacy Directive | C10: Directive 2002/58/EC | D10: Data & Privacy | E10: enacted | F10: 2000-07-12 | G10: high | H10: 2002-07-12 | I10: 2002-08-01 | J10: 2002-07-31 | K10: adopted | L10: adopted | M10: 32002L0058 | N10: Original act as published in the OJ | O10: https://eur-lex.europa.eu/legal-content/EN/TXT/?uri=CELEX:32002L0058 | P10: 11 | Q10: 8620 | R10: 5001 | S10: 4843 | T10: 3619 | U10: 0 | V10: 0 | W10: 0 | X10: 49 | Y10: 34 | Z10: 3 | AA10: 2 | AB10: 1 | AC10: 9 | AD10: 17 | AE10: 23 | AF10: 4 | AG10: 5 | AH10: 02002L0058-20091219 | AI10: 79 | AJ10: 29 | AK10: =COUNTIFS(secondary_acts!$A$2:$A$771,$A10,secondary_acts!$E$2:$E$771,"implementing") -> 0 | AL10: =COUNTIFS(secondary_acts!$A$2:$A$771,$A10,secondary_acts!$E$2:$E$771,"delegated") -> 0 | AM10: =COUNTIFS(secondary_acts!$A$2:$A$771,$A10,secondary_acts!$E$2:$E$771,"other Commission/Council act") -> 1 | AN10: =COUNTIFS(secondary_acts!$A$2:$A$771,$A10,secondary_acts!$E$2:$E$771,"guidance") -> 0 | AO10: =COUNTIF(guidance_web!$A$2:$A$7,$A10) -> 0 | AP10: =COUNTIFS(guidance_agencies!$A$2:$A$81,$A10,guidance_agencies!$D$2:$D$81,"EDPB") -> 1 | AQ10: =COUNTIFS(guidance_agencies!$A$2:$A$81,$A10,guidance_agencies!$D$2:$D$81,"EBA") -> 0 | AR10: =COUNTIFS(guidance_agencies!$A$2:$A$81,$A10,guidance_agencies!$D$2:$D$81,"ESMA") -> 0 | AS10: =SUMIFS(secondary_acts!$S$2:$S$771,secondary_acts!$A$2:$A$771,$A10,secondary_acts!$E$2:$E$771,"implementing")+SUMIFS(secondary_acts!$S$2:$S$771,secondary_acts!$A$2:$A$771,$A10,secondary_acts!$E$2:$E$771,"delegated") -> 0 | AT10: 1004 | AU10: 28 | AV10: 2 | AW10: 2006-03-15 | AX10: 2009-11-25 | AY10: 4 | AZ10: 52000PC0385 | BA10: EUR-Lex HTML | BB10: 5154 | BC10: 39 | BD10: 14 | BE10: =IF(ISNUMBER(BB10),Q10-BB10,"") -> 3466 | BF10: =IF(AND(ISNUMBER(BB10),BB10>0),(Q10-BB10)/BB10,"") -> 0.67248739 | BG10: =IF(ISNUMBER(BC10),X10-BC10,"") -> 10 | BH10: =IF(AND(ISNUMBER(BC10),BC10>0),(X10-BC10)/BC10,"") -> 0.25641026 | BI10: =IF(ISNUMBER(BD10),AD10-BD10,"") -> 3
A11: 10 | B11: Radio Spectrum Decision | C11: Decision 676/2002/EC | D11: Connectivity | E11: enacted | F11: 2000-07-12 | G11: medium | H11: 2002-03-07 | I11: 2002-04-25 | J11: 2002-04-24 | K11: adopted | L11: adopted | M11: 32002D0676 | N11: Original act as published in the OJ | O11: https://eur-lex.europa.eu/legal-content/EN/TXT/?uri=CELEX:32002D0676 | P11: 6 | Q11: 4197 | R11: 2770 | S11: 2631 | T11: 1427 | U11: 0 | V11: 0 | W11: 0 | X11: 26 | Y11: 24 | Z11: 1 | AA11: 0 | AB11: 0 | AC11: 1 | AD11: 0 | AE11: 10 | AF11: 11 | AG11: 5 | AH11: 02002D0676-20020424 | AI11: 26 | AJ11: 0 | AK11: =COUNTIFS(secondary_acts!$A$2:$A$771,$A11,secondary_acts!$E$2:$E$771,"implementing") -> 47 | AL11: =COUNTIFS(secondary_acts!$A$2:$A$771,$A11,secondary_acts!$E$2:$E$771,"delegated") -> 0 | AM11: =COUNTIFS(secondary_acts!$A$2:$A$771,$A11,secondary_acts!$E$2:$E$771,"other Commission/Council act") -> 0 | AN11: =COUNTIFS(secondary_acts!$A$2:$A$771,$A11,secondary_acts!$E$2:$E$771,"guidance") -> 0 | AO11: =COUNTIF(guidance_web!$A$2:$A$7,$A11) -> 0 | AP11: =COUNTIFS(guidance_agencies!$A$2:$A$81,$A11,guidance_agencies!$D$2:$D$81,"EDPB") -> 0 | AQ11: =COUNTIFS(guidance_agencies!$A$2:$A$81,$A11,guidance_agencies!$D$2:$D$81,"EBA") -> 0 | AR11: =COUNTIFS(guidance_agencies!$A$2:$A$81,$A11,guidance_agencies!$D$2:$D$81,"ESMA") -> 0 | AS11: =SUMIFS(secondary_acts!$S$2:$S$771,secondary_acts!$A$2:$A$771,$A11,secondary_acts!$E$2:$E$771,"implementing")+SUMIFS(secondary_acts!$S$2:$S$771,secondary_acts!$A$2:$A$771,$A11,secondary_acts!$E$2:$E$771,"delegated") -> 818 | AV11: 0 | AY11: 1 | AZ11: 52000PC0407 | BA11: PDF text (approximate) | BB11: 4076 | BC11: 33 | BD11: 0 | BE11: =IF(ISNUMBER(BB11),Q11-BB11,"") -> 121 | BF11: =IF(AND(ISNUMBER(BB11),BB11>0),(Q11-BB11)/BB11,"") -> 0.029685967 | BG11: =IF(ISNUMBER(BC11),X11-BC11,"") -> -7 | BH11: =IF(AND(ISNUMBER(BC11),BC11>0),(X11-BC11)/BC11,"") -> -0.21212121 | BI11: =IF(ISNUMBER(BD11),AD11-BD11,"") -> 0 | BJ11: no consolidated text with amendments in EUR-Lex; consolidated count = original
A12: 11 | B12: EC Merger Regulation | C12: Regulation (EC) 139/2004 | D12: Competition & Single Market | E12: enacted | F12: 2002-12-11 | G12: high | H12: 2004-01-20 | I12: 2004-01-30 | J12: 2004-02-18 | K12: adopted | L12: adopted | M12: 32004R0139 | N12: Original act as published in the OJ | O12: https://eur-lex.europa.eu/legal-content/EN/TXT/?uri=CELEX:32004R0139 | P12: 22 | Q12: 14967 | R12: 4554 | S12: 4435 | T12: 10409 | U12: 4 | V12: 0 | W12: 0 | X12: 157 | Y12: 142 | Z12: 13 | AA12: 0 | AB12: 1 | AC12: 1 | AD12: 12 | AE12: 26 | AF12: 67 | AG12: 52 | AH12: 02004R0139-20040218 | AI12: 157 | AJ12: 12 | AK12: =COUNTIFS(secondary_acts!$A$2:$A$771,$A12,secondary_acts!$E$2:$E$771,"implementing") -> 3 | AL12: =COUNTIFS(secondary_acts!$A$2:$A$771,$A12,secondary_acts!$E$2:$E$771,"delegated") -> 0 | AM12: =COUNTIFS(secondary_acts!$A$2:$A$771,$A12,secondary_acts!$E$2:$E$771,"other Commission/Council act") -> 2 | AN12: =COUNTIFS(secondary_acts!$A$2:$A$771,$A12,secondary_acts!$E$2:$E$771,"guidance") -> 3 | AO12: =COUNTIF(guidance_web!$A$2:$A$7,$A12) -> 0 | AP12: =COUNTIFS(guidance_agencies!$A$2:$A$81,$A12,guidance_agencies!$D$2:$D$81,"EDPB") -> 0 | AQ12: =COUNTIFS(guidance_agencies!$A$2:$A$81,$A12,guidance_agencies!$D$2:$D$81,"EBA") -> 0 | AR12: =COUNTIFS(guidance_agencies!$A$2:$A$81,$A12,guidance_agencies!$D$2:$D$81,"ESMA") -> 0 | AS12: =SUMIFS(secondary_acts!$S$2:$S$771,secondary_acts!$A$2:$A$771,$A12,secondary_acts!$E$2:$E$771,"implementing")+SUMIFS(secondary_acts!$S$2:$S$771,secondary_acts!$A$2:$A$771,$A12,secondary_acts!$E$2:$E$771,"delegated") -> 355 | AV12: 0 | AY12: 8 | BA12: not comparable: proposal COM(2002) 711 not available in EUR-Lex | BE12: =IF(ISNUMBER(BB12),Q12-BB12,"") | BF12: =IF(AND(ISNUMBER(BB12),BB12>0),(Q12-BB12)/BB12,"") | BG12: =IF(ISNUMBER(BC12),X12-BC12,"") | BH12: =IF(AND(ISNUMBER(BC12),BC12>0),(X12-BC12)/BC12,"") | BI12: =IF(ISNUMBER(BD12),AD12-BD12,"") | BJ12: no consolidated text with amendments in EUR-Lex; consolidated count = original
A13: 12 | B13: IPR Enforcement Directive | C13: Directive 2004/48/EC | D13: IPR | E13: enacted | F13: 2003-01-30 | G13: high | H13: 2004-04-29 | I13: 2004-07-08 | J13: 2004-05-20 | K13: adopted | L13: adopted | M13: 32004L0048 | N13: Original act as published in the OJ | O13: https://eur-lex.europa.eu/legal-content/EN/TXT/?uri=CELEX:32004L0048 | P13: 42 | Q13: 5981 | R13: 2560 | S13: 2452 | T13: 3421 | U13: 0 | V13: 0 | W13: 0 | X13: 54 | Y13: 39 | Z13: 1 | AA13: 0 | AB13: 0 | AC13: 14 | AD13: 4 | AE13: 37 | AF13: 2 | AG13: 11 | AH13: 02004L0048-20040430 | AI13: 54 | AJ13: 4 | AK13: =COUNTIFS(secondary_acts!$A$2:$A$771,$A13,secondary_acts!$E$2:$E$771,"implementing") -> 0 | AL13: =COUNTIFS(secondary_acts!$A$2:$A$771,$A13,secondary_acts!$E$2:$E$771,"delegated") -> 0 | AM13: =COUNTIFS(secondary_acts!$A$2:$A$771,$A13,secondary_acts!$E$2:$E$771,"other Commission/Council act") -> 0 | AN13: =COUNTIFS(secondary_acts!$A$2:$A$771,$A13,secondary_acts!$E$2:$E$771,"guidance") -> 1 | AO13: =COUNTIF(guidance_web!$A$2:$A$7,$A13) -> 0 | AP13: =COUNTIFS(guidance_agencies!$A$2:$A$81,$A13,guidance_agencies!$D$2:$D$81,"EDPB") -> 0 | AQ13: =COUNTIFS(guidance_agencies!$A$2:$A$81,$A13,guidance_agencies!$D$2:$D$81,"EBA") -> 0 | AR13: =COUNTIFS(guidance_agencies!$A$2:$A$81,$A13,guidance_agencies!$D$2:$D$81,"ESMA") -> 0 | AS13: =SUMIFS(secondary_acts!$S$2:$S$771,secondary_acts!$A$2:$A$771,$A13,secondary_acts!$E$2:$E$771,"implementing")+SUMIFS(secondary_acts!$S$2:$S$771,secondary_acts!$A$2:$A$771,$A13,secondary_acts!$E$2:$E$771,"delegated") -> 0 | AT13: 2025 | AU13: 28 | AV13: 0 | AY13: 4 | AZ13: 52003PC0046 | BA13: PDF text (approximate) | BB13: 8819 | BC13: 77 | BD13: 5 | BE13: =IF(ISNUMBER(BB13),Q13-BB13,"") -> -2838 | BF13: =IF(AND(ISNUMBER(BB13),BB13>0),(Q13-BB13)/BB13,"") -> -0.32180519 | BG13: =IF(ISNUMBER(BC13),X13-BC13,"") -> -23 | BH13: =IF(AND(ISNUMBER(BC13),BC13>0),(X13-BC13)/BC13,"") -> -0.2987013 | BI13: =IF(ISNUMBER(BD13),AD13-BD13,"") -> -1
A14: 13 | B14: Unfair Commercial Practices Directive | C14: Directive 2005/29/EC | D14: E-commerce & Consumer Protection | E14: enacted | F14: 2003-06-18 | G14: high | H14: 2005-05-11 | I14: 2005-06-16 | J14: 2005-06-12 | K14: adopted | L14: adopted | M14: 32005L0029 | N14: Original act as published in the OJ | O14: https://eur-lex.europa.eu/legal-content/EN/TXT/?uri=CELEX:32005L0029 | P14: 18 | Q14: 9287 | R14: 3037 | S14: 2890 | T14: 4387 | U14: 1863 | V14: 0 | W14: 0 | X14: 48 | Y14: 44 | Z14: 1 | AA14: 1 | AB14: 0 | AC14: 2 | AD14: 5 | AE14: 29 | AF14: 2 | AG14: 12 | AH14: 02005L0029-20260927 | AI14: 56 | AJ14: 5 | AK14: =COUNTIFS(secondary_acts!$A$2:$A$771,$A14,secondary_acts!$E$2:$E$771,"implementing") -> 0 | AL14: =COUNTIFS(secondary_acts!$A$2:$A$771,$A14,secondary_acts!$E$2:$E$771,"delegated") -> 0 | AM14: =COUNTIFS(secondary_acts!$A$2:$A$771,$A14,secondary_acts!$E$2:$E$771,"other Commission/Council act") -> 0 | AN14: =COUNTIFS(secondary_acts!$A$2:$A$771,$A14,secondary_acts!$E$2:$E$771,"guidance") -> 2 | AO14: =COUNTIF(guidance_web!$A$2:$A$7,$A14) -> 0 | AP14: =COUNTIFS(guidance_agencies!$A$2:$A$81,$A14,guidance_agencies!$D$2:$D$81,"EDPB") -> 0 | AQ14: =COUNTIFS(guidance_agencies!$A$2:$A$81,$A14,guidance_agencies!$D$2:$D$81,"EBA") -> 0 | AR14: =COUNTIFS(guidance_agencies!$A$2:$A$81,$A14,guidance_agencies!$D$2:$D$81,"ESMA") -> 0 | AS14: =SUMIFS(secondary_acts!$S$2:$S$771,secondary_acts!$A$2:$A$771,$A14,secondary_acts!$E$2:$E$771,"implementing")+SUMIFS(secondary_acts!$S$2:$S$771,secondary_acts!$A$2:$A$771,$A14,secondary_acts!$E$2:$E$771,"delegated") -> 0 | AT14: 3206 | AU14: 28 | AV14: 2 | AW14: 2019-11-27 | AX14: 2024-02-28 | AY14: 4 | AZ14: 52003PC0356 | BA14: PDF text (approximate) | BB14: 6830 | BC14: 33 | BD14: 1 | BE14: =IF(ISNUMBER(BB14),Q14-BB14,"") -> 2457 | BF14: =IF(AND(ISNUMBER(BB14),BB14>0),(Q14-BB14)/BB14,"") -> 0.35973646 | BG14: =IF(ISNUMBER(BC14),X14-BC14,"") -> 15 | BH14: =IF(AND(ISNUMBER(BC14),BC14>0),(X14-BC14)/BC14,"") -> 0.45454545 | BI14: =IF(ISNUMBER(BD14),AD14-BD14,"") -> 4
A15: 14 | B15: Common VAT system Directive | C15: Directive 2006/112/EC | D15: Finance | E15: enacted | F15: 2004-04-15 | G15: medium | H15: 2006-11-28 | I15: 2006-12-12 | J15: 2007-01-01 | K15: adopted | L15: adopted | M15: 32006L0112 | N15: Original act as published in the OJ | O15: https://eur-lex.europa.eu/legal-content/EN/TXT/?uri=CELEX:32006L0112 | P15: 118 | Q15: 58443 | R15: 3612 | S15: 3532 | T15: 43412 | U15: 11419 | V15: 0 | W15: 0 | X15: 406 | Y15: 349 | Z15: 48 | AA15: 0 | AB15: 6 | AC15: 3 | AD15: 57 | AE15: 144 | AF15: 40 | AG15: 165 | AH15: 02006L0112-20100811 | AI15: 425 | AJ15: 64 | AK15: =COUNTIFS(secondary_acts!$A$2:$A$771,$A15,secondary_acts!$E$2:$E$771,"implementing") -> 183 | AL15: =COUNTIFS(secondary_acts!$A$2:$A$771,$A15,secondary_acts!$E$2:$E$771,"delegated") -> 0 | AM15: =COUNTIFS(secondary_acts!$A$2:$A$771,$A15,secondary_acts!$E$2:$E$771,"other Commission/Council act") -> 1 | AN15: =COUNTIFS(secondary_acts!$A$2:$A$771,$A15,secondary_acts!$E$2:$E$771,"guidance") -> 0 | AO15: =COUNTIF(guidance_web!$A$2:$A$7,$A15) -> 0 | AP15: =COUNTIFS(guidance_agencies!$A$2:$A$81,$A15,guidance_agencies!$D$2:$D$81,"EDPB") -> 0 | AQ15: =COUNTIFS(guidance_agencies!$A$2:$A$81,$A15,guidance_agencies!$D$2:$D$81,"EBA") -> 0 | AR15: =COUNTIFS(guidance_agencies!$A$2:$A$81,$A15,guidance_agencies!$D$2:$D$81,"ESMA") -> 0 | AS15: =SUMIFS(secondary_acts!$S$2:$S$771,secondary_acts!$A$2:$A$771,$A15,secondary_acts!$E$2:$E$771,"implementing")+SUMIFS(secondary_acts!$S$2:$S$771,secondary_acts!$A$2:$A$771,$A15,secondary_acts!$E$2:$E$771,"delegated") -> 487 | AT15: 1745 | AU15: 26 | AV15: 35 | AW15: 2006-12-19 | AX15: 2025-07-18 | AY15: 23 | AZ15: 52004PC0246 | BA15: not comparable: recast proposal: PDF includes struck-through and correlation material | BE15: =IF(ISNUMBER(BB15),Q15-BB15,"") | BF15: =IF(AND(ISNUMBER(BB15),BB15>0),(Q15-BB15)/BB15,"") | BG15: =IF(ISNUMBER(BC15),X15-BC15,"") | BH15: =IF(AND(ISNUMBER(BC15),BC15>0),(X15-BC15)/BC15,"") | BI15: =IF(ISNUMBER(BD15),AD15-BD15,"")
A16: 15 | B16: Audiovisual Media Services Directive | C16: Directive 2010/13/EU | D16: Media | E16: enacted | F16: 2005-12-13 | G16: medium | H16: 2010-03-10 | I16: 2010-03-10 | J16: 2010-05-05 | K16: adopted | L16: adopted | M16: 32010L0013 | N16: Original act as published in the OJ | O16: https://eur-lex.europa.eu/legal-content/EN/TXT/?uri=CELEX:32010L0013 | P16: 24 | Q16: 15640 | R16: 8388 | S16: 8276 | T16: 6686 | U16: 566 | V16: 0 | W16: 0 | X16: 117 | Y16: 67 | Z16: 29 | AA16: 2 | AB16: 1 | AC16: 18 | AD16: 9 | AE16: 52 | AF16: 14 | AG16: 42 | AH16: 02010L0013-20250208 | AI16: 235 | AJ16: 17 | AK16: =COUNTIFS(secondary_acts!$A$2:$A$771,$A16,secondary_acts!$E$2:$E$771,"implementing") -> 0 | AL16: =COUNTIFS(secondary_acts!$A$2:$A$771,$A16,secondary_acts!$E$2:$E$771,"delegated") -> 0 | AM16: =COUNTIFS(secondary_acts!$A$2:$A$771,$A16,secondary_acts!$E$2:$E$771,"other Commission/Council act") -> 0 | AN16: =COUNTIFS(secondary_acts!$A$2:$A$771,$A16,secondary_acts!$E$2:$E$771,"guidance") -> 3 | AO16: =COUNTIF(guidance_web!$A$2:$A$7,$A16) -> 0 | AP16: =COUNTIFS(guidance_agencies!$A$2:$A$81,$A16,guidance_agencies!$D$2:$D$81,"EDPB") -> 0 | AQ16: =COUNTIFS(guidance_agencies!$A$2:$A$81,$A16,guidance_agencies!$D$2:$D$81,"EBA") -> 0 | AR16: =COUNTIFS(guidance_agencies!$A$2:$A$81,$A16,guidance_agencies!$D$2:$D$81,"ESMA") -> 0 | AS16: =SUMIFS(secondary_acts!$S$2:$S$771,secondary_acts!$A$2:$A$771,$A16,secondary_acts!$E$2:$E$771,"implementing")+SUMIFS(secondary_acts!$S$2:$S$771,secondary_acts!$A$2:$A$771,$A16,secondary_acts!$E$2:$E$771,"delegated") -> 0 | AT16: 471 | AU16: 19 | AV16: 2 | AW16: 2018-11-14 | AX16: 2024-04-11 | AY16: 3 | AZ16: 52009PC0185 | BA16: EUR-Lex HTML | BB16: 17291 | BC16: 117 | BD16: 9 | BE16: =IF(ISNUMBER(BB16),Q16-BB16,"") -> -1651 | BF16: =IF(AND(ISNUMBER(BB16),BB16>0),(Q16-BB16)/BB16,"") -> -0.095483199 | BG16: =IF(ISNUMBER(BC16),X16-BC16,"") -> 0 | BH16: =IF(AND(ISNUMBER(BC16),BC16>0),(X16-BC16)/BC16,"") -> 0 | BI16: =IF(ISNUMBER(BD16),AD16-BD16,"") -> 0
A17: 16 | B17: European Statistics Regulation | C17: Regulation (EC) 223/2009 | D17: Data & Privacy | E17: enacted | F17: 2007-10-16 | G17: high | H17: 2009-03-11 | I17: 2009-04-02 | J17: 2009-04-01 | K17: adopted | L17: adopted | M17: 32009R0223 | N17: Original act as published in the OJ | O17: https://eur-lex.europa.eu/legal-content/EN/TXT/?uri=CELEX:32009R0223 | P17: 10 | Q17: 6514 | R17: 2317 | S17: 2143 | T17: 4197 | U17: 0 | V17: 0 | W17: 0 | X17: 85 | Y17: 81 | Z17: 1 | AA17: 0 | AB17: 2 | AC17: 1 | AD17: 5 | AE17: 5 | AF17: 37 | AG17: 38 | AH17: 02009R0223-20241226 | AI17: 175 | AJ17: 10 | AK17: =COUNTIFS(secondary_acts!$A$2:$A$771,$A17,secondary_acts!$E$2:$E$771,"implementing") -> 1 | AL17: =COUNTIFS(secondary_acts!$A$2:$A$771,$A17,secondary_acts!$E$2:$E$771,"delegated") -> 0 | AM17: =COUNTIFS(secondary_acts!$A$2:$A$771,$A17,secondary_acts!$E$2:$E$771,"other Commission/Council act") -> 2 | AN17: =COUNTIFS(secondary_acts!$A$2:$A$771,$A17,secondary_acts!$E$2:$E$771,"guidance") -> 0 | AO17: =COUNTIF(guidance_web!$A$2:$A$7,$A17) -> 0 | AP17: =COUNTIFS(guidance_agencies!$A$2:$A$81,$A17,guidance_agencies!$D$2:$D$81,"EDPB") -> 0 | AQ17: =COUNTIFS(guidance_agencies!$A$2:$A$81,$A17,guidance_agencies!$D$2:$D$81,"EBA") -> 0 | AR17: =COUNTIFS(guidance_agencies!$A$2:$A$81,$A17,guidance_agencies!$D$2:$D$81,"ESMA") -> 0 | AS17: =SUMIFS(secondary_acts!$S$2:$S$771,secondary_acts!$A$2:$A$771,$A17,secondary_acts!$E$2:$E$771,"implementing")+SUMIFS(secondary_acts!$S$2:$S$771,secondary_acts!$A$2:$A$771,$A17,secondary_acts!$E$2:$E$771,"delegated") -> 43 | AV17: 2 | AW17: 2015-04-29 | AX17: 2024-11-27 | AY17: 2 | AZ17: 52007PC0625 | BA17: EUR-Lex HTML | BB17: 5421 | BC17: 68 | BD17: 4 | BE17: =IF(ISNUMBER(BB17),Q17-BB17,"") -> 1093 | BF17: =IF(AND(ISNUMBER(BB17),BB17>0),(Q17-BB17)/BB17,"") -> 0.20162332 | BG17: =IF(ISNUMBER(BC17),X17-BC17,"") -> 17 | BH17: =IF(AND(ISNUMBER(BC17),BC17>0),(X17-BC17)/BC17,"") -> 0.25 | BI17: =IF(ISNUMBER(BD17),AD17-BD17,"") -> 1
A18: 17 | B18: Toys Safety Directive | C18: Directive 2009/48/EC | D18: Trust & Safety | E18: enacted | F18: 2008-01-25 | G18: high | H18: 2009-06-18 | I18: 2009-06-18 | J18: 2009-07-20 | K18: adopted | L18: adopted | M18: 32009L0048 | N18: Original act as published in the OJ | O18: https://eur-lex.europa.eu/legal-content/EN/TXT/?uri=CELEX:32009L0048 | P18: 37 | Q18: 19379 | R18: 3870 | S18: 3771 | T18: 9594 | U18: 5915 | V18: 0 | W18: 0 | X18: 329 | Y18: 270 | Z18: 37 | AA18: 3 | AB18: 0 | AC18: 19 | AD18: 88 | AE18: 59 | AF18: 37 | AG18: 145 | AH18: 02009L0048-20260829 | AI18: 329 | AJ18: 88 | AK18: =COUNTIFS(secondary_acts!$A$2:$A$771,$A18,secondary_acts!$E$2:$E$771,"implementing") -> 1 | AL18: =COUNTIFS(secondary_acts!$A$2:$A$771,$A18,secondary_acts!$E$2:$E$771,"delegated") -> 0 | AM18: =COUNTIFS(secondary_acts!$A$2:$A$771,$A18,secondary_acts!$E$2:$E$771,"other Commission/Council act") -> 18 | AN18: =COUNTIFS(secondary_acts!$A$2:$A$771,$A18,secondary_acts!$E$2:$E$771,"guidance") -> 0 | AO18: =COUNTIF(guidance_web!$A$2:$A$7,$A18) -> 0 | AP18: =COUNTIFS(guidance_agencies!$A$2:$A$81,$A18,guidance_agencies!$D$2:$D$81,"EDPB") -> 0 | AQ18: =COUNTIFS(guidance_agencies!$A$2:$A$81,$A18,guidance_agencies!$D$2:$D$81,"EBA") -> 0 | AR18: =COUNTIFS(guidance_agencies!$A$2:$A$81,$A18,guidance_agencies!$D$2:$D$81,"ESMA") -> 0 | AS18: =SUMIFS(secondary_acts!$S$2:$S$771,secondary_acts!$A$2:$A$771,$A18,secondary_acts!$E$2:$E$771,"implementing")+SUMIFS(secondary_acts!$S$2:$S$771,secondary_acts!$A$2:$A$771,$A18,secondary_acts!$E$2:$E$771,"delegated") -> 0 | AT18: 1613 | AU18: 15 | AV18: 18 | AW18: 2012-03-02 | AX18: 2026-01-28 | AY18: 5 | AZ18: 52008PC0009 | BA18: EUR-Lex HTML | BB18: 14934 | BC18: 283 | BD18: 85 | BE18: =IF(ISNUMBER(BB18),Q18-BB18,"") -> 4445 | BF18: =IF(AND(ISNUMBER(BB18),BB18>0),(Q18-BB18)/BB18,"") -> 0.29764296 | BG18: =IF(ISNUMBER(BC18),X18-BC18,"") -> 46 | BH18: =IF(AND(ISNUMBER(BC18),BC18>0),(X18-BC18)/BC18,"") -> 0.16254417 | BI18: =IF(ISNUMBER(BD18),AD18-BD18,"") -> 3
A19: 18 | B19: Consumer Rights Directive | C19: Directive 2011/83/EU | D19: E-commerce & Consumer Protection | E19: enacted | F19: 2008-10-08 | G19: high | H19: 2011-10-25 | I19: 2011-11-22 | J19: 2011-12-12 | K19: adopted | L19: adopted | M19: 32011L0083 | N19: Original act as published in the OJ | O19: https://eur-lex.europa.eu/legal-content/EN/TXT/?uri=CELEX:32011L0083 | P19: 25 | Q19: 16782 | R19: 7167 | S19: 7021 | T19: 7762 | U19: 1853 | V19: 0 | W19: 0 | X19: 105 | Y19: 82 | Z19: 17 | AA19: 1 | AB19: 1 | AC19: 4 | AD19: 47 | AE19: 23 | AF19: 5 | AG19: 30 | AH19: 02011L0083-20260927 | AI19: 182 | AJ19: 87 | AK19: =COUNTIFS(secondary_acts!$A$2:$A$771,$A19,secondary_acts!$E$2:$E$771,"implementing") -> 1 | AL19: =COUNTIFS(secondary_acts!$A$2:$A$771,$A19,secondary_acts!$E$2:$E$771,"delegated") -> 0 | AM19: =COUNTIFS(secondary_acts!$A$2:$A$771,$A19,secondary_acts!$E$2:$E$771,"other Commission/Council act") -> 0 | AN19: =COUNTIFS(secondary_acts!$A$2:$A$771,$A19,secondary_acts!$E$2:$E$771,"guidance") -> 1 | AO19: =COUNTIF(guidance_web!$A$2:$A$7,$A19) -> 0 | AP19: =COUNTIFS(guidance_agencies!$A$2:$A$81,$A19,guidance_agencies!$D$2:$D$81,"EDPB") -> 0 | AQ19: =COUNTIFS(guidance_agencies!$A$2:$A$81,$A19,guidance_agencies!$D$2:$D$81,"EBA") -> 0 | AR19: =COUNTIFS(guidance_agencies!$A$2:$A$81,$A19,guidance_agencies!$D$2:$D$81,"ESMA") -> 0 | AS19: =SUMIFS(secondary_acts!$S$2:$S$771,secondary_acts!$A$2:$A$771,$A19,secondary_acts!$E$2:$E$771,"implementing")+SUMIFS(secondary_acts!$S$2:$S$771,secondary_acts!$A$2:$A$771,$A19,secondary_acts!$E$2:$E$771,"delegated") -> 13 | AT19: 1559 | AU19: 28 | AV19: 4 | AW19: 2015-11-25 | AX19: 2024-02-28 | AY19: 6 | AZ19: 52008PC0614 | BA19: EUR-Lex HTML | BB19: 14168 | BC19: 98 | BD19: 40 | BE19: =IF(ISNUMBER(BB19),Q19-BB19,"") -> 2614 | BF19: =IF(AND(ISNUMBER(BB19),BB19>0),(Q19-BB19)/BB19,"") -> 0.18450028 | BG19: =IF(ISNUMBER(BC19),X19-BC19,"") -> 7 | BH19: =IF(AND(ISNUMBER(BC19),BC19>0),(X19-BC19)/BC19,"") -> 0.071428571 | BI19: =IF(ISNUMBER(BD19),AD19-BD19,"") -> 7
A20: 19 | B20: Administrative cooperation in taxation (DAC) | C20: Directive 2011/16/EU | D20: Finance | E20: enacted | F20: 2009-02-02 | G20: high | H20: 2011-02-15 | I20: 2011-02-15 | J20: 2011-03-11 | K20: adopted | L20: adopted | M20: 32011L0016 | N20: Original act as published in the OJ | O20: https://eur-lex.europa.eu/legal-content/EN/TXT/?uri=CELEX:32011L0016 | P20: 12 | Q20: 7830 | R20: 1814 | S20: 1712 | T20: 6016 | U20: 0 | V20: 0 | W20: 0 | X20: 111 | Y20: 100 | Z20: 5 | AA20: 3 | AB20: 3 | AC20: 0 | AD20: 2 | AE20: 69 | AF20: 17 | AG20: 23 | AH20: 02011L0016-20260101 | AI20: 613 | AJ20: 158 | AK20: =COUNTIFS(secondary_acts!$A$2:$A$771,$A20,secondary_acts!$E$2:$E$771,"implementing") -> 14 | AL20: =COUNTIFS(secondary_acts!$A$2:$A$771,$A20,secondary_acts!$E$2:$E$771,"delegated") -> 0 | AM20: =COUNTIFS(secondary_acts!$A$2:$A$771,$A20,secondary_acts!$E$2:$E$771,"other Commission/Council act") -> 0 | AN20: =COUNTIFS(secondary_acts!$A$2:$A$771,$A20,secondary_acts!$E$2:$E$771,"guidance") -> 0 | AO20: =COUNTIF(guidance_web!$A$2:$A$7,$A20) -> 0 | AP20: =COUNTIFS(guidance_agencies!$A$2:$A$81,$A20,guidance_agencies!$D$2:$D$81,"EDPB") -> 0 | AQ20: =COUNTIFS(guidance_agencies!$A$2:$A$81,$A20,guidance_agencies!$D$2:$D$81,"EBA") -> 0 | AR20: =COUNTIFS(guidance_agencies!$A$2:$A$81,$A20,guidance_agencies!$D$2:$D$81,"ESMA") -> 0 | AS20: =SUMIFS(secondary_acts!$S$2:$S$771,secondary_acts!$A$2:$A$771,$A20,secondary_acts!$E$2:$E$771,"implementing")+SUMIFS(secondary_acts!$S$2:$S$771,secondary_acts!$A$2:$A$771,$A20,secondary_acts!$E$2:$E$771,"delegated") -> 100 | AT20: 380 | AU20: 28 | AV20: 9 | AW20: 2014-12-09 | AX20: 2025-04-14 | AY20: 5 | AZ20: 52009PC0029 | BA20: EUR-Lex HTML | BB20: 6065 | BC20: 93 | BD20: 2 | BE20: =IF(ISNUMBER(BB20),Q20-BB20,"") -> 1765 | BF20: =IF(AND(ISNUMBER(BB20),BB20>0),(Q20-BB20)/BB20,"") -> 0.29101401 | BG20: =IF(ISNUMBER(BC20),X20-BC20,"") -> 18 | BH20: =IF(AND(ISNUMBER(BC20),BC20>0),(X20-BC20)/BC20,"") -> 0.19354839 | BI20: =IF(ISNUMBER(BD20),AD20-BD20,"") -> 0
A21: 20 | B21: General Data Protection Regulation | C21: Regulation (EU) 2016/679 | D21: Data & Privacy | E21: enacted | F21: 2012-01-25 | G21: high | H21: 2016-04-27 | I21: 2016-05-04 | J21: 2016-05-24 | K21: adopted | L21: adopted | M21: 32016R0679 | N21: Original act as published in the OJ | O21: https://eur-lex.europa.eu/legal-content/EN/TXT/?uri=CELEX:32016R0679 | P21: 88 | Q21: 54331 | R21: 23839 | S21: 23692 | T21: 30492 | U21: 0 | V21: 0 | W21: 0 | X21: 417 | Y21: 370 | Z21: 24 | AA21: 3 | AB21: 8 | AC21: 12 | AD21: 99 | AE21: 129 | AF21: 81 | AG21: 108 | AH21: 02016R0679-20160504 | AI21: 415 | AJ21: 99 | AK21: =COUNTIFS(secondary_acts!$A$2:$A$771,$A21,secondary_acts!$E$2:$E$771,"implementing") -> 11 | AL21: =COUNTIFS(secondary_acts!$A$2:$A$771,$A21,secondary_acts!$E$2:$E$771,"delegated") -> 0 | AM21: =COUNTIFS(secondary_acts!$A$2:$A$771,$A21,secondary_acts!$E$2:$E$771,"other Commission/Council act") -> 0 | AN21: =COUNTIFS(secondary_acts!$A$2:$A$771,$A21,secondary_acts!$E$2:$E$771,"guidance") -> 2 | AO21: =COUNTIF(guidance_web!$A$2:$A$7,$A21) -> 0 | AP21: =COUNTIFS(guidance_agencies!$A$2:$A$81,$A21,guidance_agencies!$D$2:$D$81,"EDPB") -> 47 | AQ21: =COUNTIFS(guidance_agencies!$A$2:$A$81,$A21,guidance_agencies!$D$2:$D$81,"EBA") -> 0 | AR21: =COUNTIFS(guidance_agencies!$A$2:$A$81,$A21,guidance_agencies!$D$2:$D$81,"ESMA") -> 0 | AS21: =SUMIFS(secondary_acts!$S$2:$S$771,secondary_acts!$A$2:$A$771,$A21,secondary_acts!$E$2:$E$771,"implementing")+SUMIFS(secondary_acts!$S$2:$S$771,secondary_acts!$A$2:$A$771,$A21,secondary_acts!$E$2:$E$771,"delegated") -> 927 | AV21: 0 | AY21: 3 | AZ21: 52012PC0011 | BA21: EUR-Lex HTML | BB21: 35380 | BC21: 362 | BD21: 78 | BE21: =IF(ISNUMBER(BB21),Q21-BB21,"") -> 18951 | BF21: =IF(AND(ISNUMBER(BB21),BB21>0),(Q21-BB21)/BB21,"") -> 0.53564161 | BG21: =IF(ISNUMBER(BC21),X21-BC21,"") -> 55 | BH21: =IF(AND(ISNUMBER(BC21),BC21>0),(X21-BC21)/BC21,"") -> 0.1519337 | BI21: =IF(ISNUMBER(BD21),AD21-BD21,"") -> 21
A22: 21 | B22: Law Enforcement Directive | C22: Directive (EU) 2016/680 | D22: Law Enforcement | E22: enacted | F22: 2012-01-25 | G22: high | H22: 2016-04-27 | I22: 2016-05-04 | J22: 2016-05-05 | K22: adopted | L22: adopted | M22: 32016L0680 | N22: Original act as published in the OJ | O22: https://eur-lex.europa.eu/legal-content/EN/TXT/?uri=CELEX:32016L0680 | P22: 43 | Q22: 26710 | R22: 12941 | S22: 12790 | T22: 13769 | U22: 0 | V22: 0 | W22: 0 | X22: 225 | Y22: 206 | Z22: 11 | AA22: 1 | AB22: 2 | AC22: 5 | AD22: 25 | AE22: 129 | AF22: 26 | AG22: 45 | AH22: 02016L0680-20160504 | AI22: 225 | AJ22: 25 | AK22: =COUNTIFS(secondary_acts!$A$2:$A$771,$A22,secondary_acts!$E$2:$E$771,"implementing") -> 3 | AL22: =COUNTIFS(secondary_acts!$A$2:$A$771,$A22,secondary_acts!$E$2:$E$771,"delegated") -> 0 | AM22: =COUNTIFS(secondary_acts!$A$2:$A$771,$A22,secondary_acts!$E$2:$E$771,"other Commission/Council act") -> 0 | AN22: =COUNTIFS(secondary_acts!$A$2:$A$771,$A22,secondary_acts!$E$2:$E$771,"guidance") -> 0 | AO22: =COUNTIF(guidance_web!$A$2:$A$7,$A22) -> 0 | AP22: =COUNTIFS(guidance_agencies!$A$2:$A$81,$A22,guidance_agencies!$D$2:$D$81,"EDPB") -> 2 | AQ22: =COUNTIFS(guidance_agencies!$A$2:$A$81,$A22,guidance_agencies!$D$2:$D$81,"EBA") -> 0 | AR22: =COUNTIFS(guidance_agencies!$A$2:$A$81,$A22,guidance_agencies!$D$2:$D$81,"ESMA") -> 0 | AS22: =SUMIFS(secondary_acts!$S$2:$S$771,secondary_acts!$A$2:$A$771,$A22,secondary_acts!$E$2:$E$771,"implementing")+SUMIFS(secondary_acts!$S$2:$S$771,secondary_acts!$A$2:$A$771,$A22,secondary_acts!$E$2:$E$771,"delegated") -> 5 | AT22: 3772 | AU22: 28 | AV22: 0 | AY22: 3 | AZ22: 52012PC0010 | BA22: EUR-Lex HTML | BB22: 16067 | BC22: 193 | BD22: 26 | BE22: =IF(ISNUMBER(BB22),Q22-BB22,"") -> 10643 | BF22: =IF(AND(ISNUMBER(BB22),BB22>0),(Q22-BB22)/BB22,"") -> 0.66241364 | BG22: =IF(ISNUMBER(BC22),X22-BC22,"") -> 32 | BH22: =IF(AND(ISNUMBER(BC22),BC22>0),(X22-BC22)/BC22,"") -> 0.16580311 | BI22: =IF(ISNUMBER(BD22),AD22-BD22,"") -> -1
A23: 22 | B23: eIDAS Regulation | C23: Regulation (EU) 910/2014 | D23: Trust & Safety | E23: enacted | F23: 2012-06-04 | G23: high | H23: 2014-07-23 | I23: 2014-08-28 | J23: 2014-09-17 | K23: adopted | L23: adopted | M23: 32014R0910 | N23: Original act as published in the OJ | O23: https://eur-lex.europa.eu/legal-content/EN/TXT/?uri=CELEX:32014R0910 | P23: 42 | Q23: 18535 | R23: 5975 | S23: 5856 | T23: 11516 | U23: 1044 | V23: 0 | W23: 0 | X23: 181 | Y23: 154 | Z23: 16 | AA23: 5 | AB23: 2 | AC23: 4 | AD23: 26 | AE23: 45 | AF23: 52 | AG23: 58 | AH23: 02014R0910-20240520 | AI23: 428 | AJ23: 76 | AK23: =COUNTIFS(secondary_acts!$A$2:$A$771,$A23,secondary_acts!$E$2:$E$771,"implementing") -> 43 | AL23: =COUNTIFS(secondary_acts!$A$2:$A$771,$A23,secondary_acts!$E$2:$E$771,"delegated") -> 0 | AM23: =COUNTIFS(secondary_acts!$A$2:$A$771,$A23,secondary_acts!$E$2:$E$771,"other Commission/Council act") -> 0 | AN23: =COUNTIFS(secondary_acts!$A$2:$A$771,$A23,secondary_acts!$E$2:$E$771,"guidance") -> 0 | AO23: =COUNTIF(guidance_web!$A$2:$A$7,$A23) -> 0 | AP23: =COUNTIFS(guidance_agencies!$A$2:$A$81,$A23,guidance_agencies!$D$2:$D$81,"EDPB") -> 0 | AQ23: =COUNTIFS(guidance_agencies!$A$2:$A$81,$A23,guidance_agencies!$D$2:$D$81,"EBA") -> 0 | AR23: =COUNTIFS(guidance_agencies!$A$2:$A$81,$A23,guidance_agencies!$D$2:$D$81,"ESMA") -> 0 | AS23: =SUMIFS(secondary_acts!$S$2:$S$771,secondary_acts!$A$2:$A$771,$A23,secondary_acts!$E$2:$E$771,"implementing")+SUMIFS(secondary_acts!$S$2:$S$771,secondary_acts!$A$2:$A$771,$A23,secondary_acts!$E$2:$E$771,"delegated") -> 1377 | AV23: 2 | AW23: 2022-12-14 | AX23: 2024-04-11 | AY23: 12 | AZ23: 52012PC0238 | BA23: EUR-Lex HTML | BB23: 12741 | BC23: 163 | BD23: 15 | BE23: =IF(ISNUMBER(BB23),Q23-BB23,"") -> 5794 | BF23: =IF(AND(ISNUMBER(BB23),BB23>0),(Q23-BB23)/BB23,"") -> 0.45475237 | BG23: =IF(ISNUMBER(BC23),X23-BC23,"") -> 18 | BH23: =IF(AND(ISNUMBER(BC23),BC23>0),(X23-BC23)/BC23,"") -> 0.11042945 | BI23: =IF(ISNUMBER(BD23),AD23-BD23,"") -> 11
A24: 23 | B24: Payment Services Directive 2 (PSD2) | C24: Directive (EU) 2015/2366 | D24: Finance | E24: enacted | F24: 2013-07-24 | G24: high | H24: 2015-11-25 | I24: 2015-12-23 | J24: 2016-01-12 | K24: adopted | L24: adopted | M24: 32015L2366 | N24: Original act as published in the OJ | O24: https://eur-lex.europa.eu/legal-content/EN/TXT/?uri=CELEX:32015L2366 | P24: 93 | Q24: 47656 | R24: 14399 | S24: 14254 | T24: 31276 | U24: 1981 | V24: 0 | W24: 0 | X24: 462 | Y24: 354 | Z24: 46 | AA24: 7 | AB24: 4 | AC24: 51 | AD24: 172 | AE24: 171 | AF24: 44 | AG24: 75 | AH24: 02015L2366-20250117 | AI24: 470 | AJ24: 173 | AK24: =COUNTIFS(secondary_acts!$A$2:$A$771,$A24,secondary_acts!$E$2:$E$771,"implementing") -> 1 | AL24: =COUNTIFS(secondary_acts!$A$2:$A$771,$A24,secondary_acts!$E$2:$E$771,"delegated") -> 8 | AM24: =COUNTIFS(secondary_acts!$A$2:$A$771,$A24,secondary_acts!$E$2:$E$771,"other Commission/Council act") -> 0 | AN24: =COUNTIFS(secondary_acts!$A$2:$A$771,$A24,secondary_acts!$E$2:$E$771,"guidance") -> 0 | AO24: =COUNTIF(guidance_web!$A$2:$A$7,$A24) -> 0 | AP24: =COUNTIFS(guidance_agencies!$A$2:$A$81,$A24,guidance_agencies!$D$2:$D$81,"EDPB") -> 1 | AQ24: =COUNTIFS(guidance_agencies!$A$2:$A$81,$A24,guidance_agencies!$D$2:$D$81,"EBA") -> 11 | AR24: =COUNTIFS(guidance_agencies!$A$2:$A$81,$A24,guidance_agencies!$D$2:$D$81,"ESMA") -> 0 | AS24: =SUMIFS(secondary_acts!$S$2:$S$771,secondary_acts!$A$2:$A$771,$A24,secondary_acts!$E$2:$E$771,"implementing")+SUMIFS(secondary_acts!$S$2:$S$771,secondary_acts!$A$2:$A$771,$A24,secondary_acts!$E$2:$E$771,"delegated") -> 468 | AT24: 2499 | AU24: 28 | AV24: 2 | AW24: 2022-12-14 | AX24: 2024-03-13 | AY24: 8 | AZ24: 52013PC0547 | BA24: EUR-Lex HTML | BB24: 34397 | BC24: 360 | BD24: 116 | BE24: =IF(ISNUMBER(BB24),Q24-BB24,"") -> 13259 | BF24: =IF(AND(ISNUMBER(BB24),BB24>0),(Q24-BB24)/BB24,"") -> 0.38546966 | BG24: =IF(ISNUMBER(BC24),X24-BC24,"") -> 102 | BH24: =IF(AND(ISNUMBER(BC24),BC24>0),(X24-BC24)/BC24,"") -> 0.28333333 | BI24: =IF(ISNUMBER(BD24),AD24-BD24,"") -> 56
A25: 24 | B25: Open Internet Access Regulation | C25: Regulation (EU) 2015/2120 | D25: Connectivity | E25: enacted | F25: 2013-09-11 | G25: high | H25: 2015-11-25 | I25: 2015-11-26 | J25: 2015-11-29 | K25: adopted | L25: adopted | M25: 32015R2120 | N25: Original act as published in the OJ | O25: https://eur-lex.europa.eu/legal-content/EN/TXT/?uri=CELEX:32015R2120 | P25: 18 | Q25: 11290 | R25: 4983 | S25: 4826 | T25: 6307 | U25: 0 | V25: 0 | W25: 0 | X25: 72 | Y25: 59 | Z25: 10 | AA25: 2 | AB25: 0 | AC25: 1 | AD25: 29 | AE25: 11 | AF25: 18 | AG25: 14 | AH25: 02015R2120-20151126 | AI25: 72 | AJ25: 29 | AK25: =COUNTIFS(secondary_acts!$A$2:$A$771,$A25,secondary_acts!$E$2:$E$771,"implementing") -> 1 | AL25: =COUNTIFS(secondary_acts!$A$2:$A$771,$A25,secondary_acts!$E$2:$E$771,"delegated") -> 0 | AM25: =COUNTIFS(secondary_acts!$A$2:$A$771,$A25,secondary_acts!$E$2:$E$771,"other Commission/Council act") -> 0 | AN25: =COUNTIFS(secondary_acts!$A$2:$A$771,$A25,secondary_acts!$E$2:$E$771,"guidance") -> 0 | AO25: =COUNTIF(guidance_web!$A$2:$A$7,$A25) -> 0 | AP25: =COUNTIFS(guidance_agencies!$A$2:$A$81,$A25,guidance_agencies!$D$2:$D$81,"EDPB") -> 0 | AQ25: =COUNTIFS(guidance_agencies!$A$2:$A$81,$A25,guidance_agencies!$D$2:$D$81,"EBA") -> 0 | AR25: =COUNTIFS(guidance_agencies!$A$2:$A$81,$A25,guidance_agencies!$D$2:$D$81,"ESMA") -> 0 | AS25: =SUMIFS(secondary_acts!$S$2:$S$771,secondary_acts!$A$2:$A$771,$A25,secondary_acts!$E$2:$E$771,"implementing")+SUMIFS(secondary_acts!$S$2:$S$771,secondary_acts!$A$2:$A$771,$A25,secondary_acts!$E$2:$E$771,"delegated") -> 10 | AV25: 2 | AW25: 2018-12-11 | AX25: 2024-04-29 | AY25: 3 | AZ25: 52013PC0627 | BA25: EUR-Lex HTML | BB25: 30255 | BC25: 293 | BD25: 44 | BE25: =IF(ISNUMBER(BB25),Q25-BB25,"") -> -18965 | BF25: =IF(AND(ISNUMBER(BB25),BB25>0),(Q25-BB25)/BB25,"") -> -0.62683854 | BG25: =IF(ISNUMBER(BC25),X25-BC25,"") -> -221 | BH25: =IF(AND(ISNUMBER(BC25),BC25>0),(X25-BC25)/BC25,"") -> -0.75426621 | BI25: =IF(ISNUMBER(BD25),AD25-BD25,"") -> -15 | BJ25: no consolidated text with amendments in EUR-Lex; consolidated count = original
A26: 25 | B26: Technology Transfer Block Exemption | C26: Regulation (EU) 316/2014 | D26: Competition & Single Market | E26: enacted | F26: 2013-02-20 | G26: low | H26: 2014-03-21 | I26: 2014-03-28 | J26: 2014-05-01 | K26: adopted | L26: adopted | M26: 32014R0316 | N26: Original act as published in the OJ | O26: https://eur-lex.europa.eu/legal-content/EN/TXT/?uri=CELEX:32014R0316 | P26: 7 | Q26: 4660 | R26: 1553 | S26: 1431 | T26: 3107 | U26: 0 | V26: 0 | W26: 0 | X26: 0 | Y26: 0 | Z26: 0 | AA26: 0 | AB26: 0 | AC26: 0 | AD26: 0 | AE26: 0 | AF26: 0 | AG26: 0 | AH26: 02014R0316-20140501 | AI26: 0 | AJ26: 0 | AK26: =COUNTIFS(secondary_acts!$A$2:$A$771,$A26,secondary_acts!$E$2:$E$771,"implementing") -> 0 | AL26: =COUNTIFS(secondary_acts!$A$2:$A$771,$A26,secondary_acts!$E$2:$E$771,"delegated") -> 0 | AM26: =COUNTIFS(secondary_acts!$A$2:$A$771,$A26,secondary_acts!$E$2:$E$771,"other Commission/Council act") -> 0 | AN26: =COUNTIFS(secondary_acts!$A$2:$A$771,$A26,secondary_acts!$E$2:$E$771,"guidance") -> 0 | AO26: =COUNTIF(guidance_web!$A$2:$A$7,$A26) -> 0 | AP26: =COUNTIFS(guidance_agencies!$A$2:$A$81,$A26,guidance_agencies!$D$2:$D$81,"EDPB") -> 0 | AQ26: =COUNTIFS(guidance_agencies!$A$2:$A$81,$A26,guidance_agencies!$D$2:$D$81,"EBA") -> 0 | AR26: =COUNTIFS(guidance_agencies!$A$2:$A$81,$A26,guidance_agencies!$D$2:$D$81,"ESMA") -> 0 | AS26: =SUMIFS(secondary_acts!$S$2:$S$771,secondary_acts!$A$2:$A$771,$A26,secondary_acts!$E$2:$E$771,"implementing")+SUMIFS(secondary_acts!$S$2:$S$771,secondary_acts!$A$2:$A$771,$A26,secondary_acts!$E$2:$E$771,"delegated") -> 0 | AV26: 0 | AY26: 2 | BA26: no legislative proposal (Commission act) | BE26: =IF(ISNUMBER(BB26),Q26-BB26,"") | BF26: =IF(AND(ISNUMBER(BB26),BB26>0),(Q26-BB26)/BB26,"") | BG26: =IF(ISNUMBER(BC26),X26-BC26,"") | BH26: =IF(AND(ISNUMBER(BC26),BC26>0),(X26-BC26)/BC26,"") | BI26: =IF(ISNUMBER(BD26),AD26-BD26,"") | BJ26: Block exemption: defines a safe harbour ('the exemption shall not apply to...'), so few direct restrictions are counted; no consolidated text with amendments in EUR-Lex; consolidated count = original
A27: 26 | B27: Trade Secrets Directive | C27: Directive (EU) 2016/943 | D27: IPR | E27: enacted | F27: 2013-11-28 | G27: high | H27: 2016-06-08 | I27: 2016-06-15 | J27: 2016-07-05 | K27: adopted | L27: adopted | M27: 32016L0943 | N27: Original act as published in the OJ | O27: https://eur-lex.europa.eu/legal-content/EN/TXT/?uri=CELEX:32016L0943 | P27: 18 | Q27: 9919 | R27: 5447 | S27: 5326 | T27: 4472 | U27: 0 | V27: 0 | W27: 0 | X27: 60 | Y27: 38 | Z27: 5 | AA27: 0 | AB27: 1 | AC27: 16 | AD27: 4 | AE27: 38 | AF27: 4 | AG27: 14 | AH27: 02016L0943-20160615 | AI27: 60 | AJ27: 4 | AK27: =COUNTIFS(secondary_acts!$A$2:$A$771,$A27,secondary_acts!$E$2:$E$771,"implementing") -> 0 | AL27: =COUNTIFS(secondary_acts!$A$2:$A$771,$A27,secondary_acts!$E$2:$E$771,"delegated") -> 0 | AM27: =COUNTIFS(secondary_acts!$A$2:$A$771,$A27,secondary_acts!$E$2:$E$771,"other Commission/Council act") -> 0 | AN27: =COUNTIFS(secondary_acts!$A$2:$A$771,$A27,secondary_acts!$E$2:$E$771,"guidance") -> 0 | AO27: =COUNTIF(guidance_web!$A$2:$A$7,$A27) -> 0 | AP27: =COUNTIFS(guidance_agencies!$A$2:$A$81,$A27,guidance_agencies!$D$2:$D$81,"EDPB") -> 0 | AQ27: =COUNTIFS(guidance_agencies!$A$2:$A$81,$A27,guidance_agencies!$D$2:$D$81,"EBA") -> 0 | AR27: =COUNTIFS(guidance_agencies!$A$2:$A$81,$A27,guidance_agencies!$D$2:$D$81,"ESMA") -> 0 | AS27: =SUMIFS(secondary_acts!$S$2:$S$771,secondary_acts!$A$2:$A$771,$A27,secondary_acts!$E$2:$E$771,"implementing")+SUMIFS(secondary_acts!$S$2:$S$771,secondary_acts!$A$2:$A$771,$A27,secondary_acts!$E$2:$E$771,"delegated") -> 0 | AT27: 1446 | AU27: 28 | AV27: 0 | AY27: 1 | AZ27: 52013PC0813 | BA27: EUR-Lex HTML | BB27: 7646 | BC27: 53 | BD27: 1 | BE27: =IF(ISNUMBER(BB27),Q27-BB27,"") -> 2273 | BF27: =IF(AND(ISNUMBER(BB27),BB27>0),(Q27-BB27)/BB27,"") -> 0.29727962 | BG27: =IF(ISNUMBER(BC27),X27-BC27,"") -> 7 | BH27: =IF(AND(ISNUMBER(BC27),BC27>0),(X27-BC27)/BC27,"") -> 0.13207547 | BI27: =IF(ISNUMBER(BD27),AD27-BD27,"") -> 3 | BJ27: no consolidated text with amendments in EUR-Lex; consolidated count = original
A28: 27 | B28: Digital Content Directive | C28: Directive (EU) 2019/770 | D28: E-commerce & Consumer Protection | E28: enacted | F28: 2015-12-09 | G28: high | H28: 2019-05-20 | I28: 2019-05-22 | J28: 2019-06-11 | K28: adopted | L28: adopted | M28: 32019L0770 | N28: Original act as published in the OJ | O28: https://eur-lex.europa.eu/legal-content/EN/TXT/?uri=CELEX:32019L0770 | P28: 27 | Q28: 18391 | R28: 12610 | S28: 12493 | T28: 5781 | U28: 0 | V28: 0 | W28: 0 | X28: 51 | Y28: 41 | Z28: 4 | AA28: 0 | AB28: 1 | AC28: 5 | AD28: 21 | AE28: 12 | AF28: 1 | AG28: 17 | AH28: 02019L0770-20190522 | AI28: 51 | AJ28: 21 | AK28: =COUNTIFS(secondary_acts!$A$2:$A$771,$A28,secondary_acts!$E$2:$E$771,"implementing") -> 0 | AL28: =COUNTIFS(secondary_acts!$A$2:$A$771,$A28,secondary_acts!$E$2:$E$771,"delegated") -> 0 | AM28: =COUNTIFS(secondary_acts!$A$2:$A$771,$A28,secondary_acts!$E$2:$E$771,"other Commission/Council act") -> 0 | AN28: =COUNTIFS(secondary_acts!$A$2:$A$771,$A28,secondary_acts!$E$2:$E$771,"guidance") -> 0 | AO28: =COUNTIF(guidance_web!$A$2:$A$7,$A28) -> 0 | AP28: =COUNTIFS(guidance_agencies!$A$2:$A$81,$A28,guidance_agencies!$D$2:$D$81,"EDPB") -> 0 | AQ28: =COUNTIFS(guidance_agencies!$A$2:$A$81,$A28,guidance_agencies!$D$2:$D$81,"EBA") -> 0 | AR28: =COUNTIFS(guidance_agencies!$A$2:$A$81,$A28,guidance_agencies!$D$2:$D$81,"ESMA") -> 0 | AS28: =SUMIFS(secondary_acts!$S$2:$S$771,secondary_acts!$A$2:$A$771,$A28,secondary_acts!$E$2:$E$771,"implementing")+SUMIFS(secondary_acts!$S$2:$S$771,secondary_acts!$A$2:$A$771,$A28,secondary_acts!$E$2:$E$771,"delegated") -> 0 | AT28: 1331 | AU28: 27 | AV28: 0 | AY28: 4 | AZ28: 52015PC0634 | BA28: EUR-Lex HTML | BB28: 9777 | BC28: 50 | BD28: 21 | BE28: =IF(ISNUMBER(BB28),Q28-BB28,"") -> 8614 | BF28: =IF(AND(ISNUMBER(BB28),BB28>0),(Q28-BB28)/BB28,"") -> 0.88104736 | BG28: =IF(ISNUMBER(BC28),X28-BC28,"") -> 1 | BH28: =IF(AND(ISNUMBER(BC28),BC28>0),(X28-BC28)/BC28,"") -> 0.02 | BI28: =IF(ISNUMBER(BD28),AD28-BD28,"") -> 0 | BJ28: no consolidated text with amendments in EUR-Lex; consolidated count = original
A29: 28 | B29: Sale of Goods Directive | C29: Directive (EU) 2019/771 | D29: E-commerce & Consumer Protection | E29: enacted | F29: 2015-12-09 | G29: high | H29: 2019-05-20 | I29: 2019-05-22 | J29: 2019-06-11 | K29: adopted | L29: adopted | M29: 32019L0771 | N29: Original act as published in the OJ | O29: https://eur-lex.europa.eu/legal-content/EN/TXT/?uri=CELEX:32019L0771 | P29: 23 | Q29: 14331 | R29: 9215 | S29: 9086 | T29: 4770 | U29: 346 | V29: 0 | W29: 0 | X29: 42 | Y29: 31 | Z29: 4 | AA29: 1 | AB29: 1 | AC29: 5 | AD29: 11 | AE29: 12 | AF29: 1 | AG29: 18 | AH29: 02019L0771-20260731 | AI29: 44 | AJ29: 12 | AK29: =COUNTIFS(secondary_acts!$A$2:$A$771,$A29,secondary_acts!$E$2:$E$771,"implementing") -> 0 | AL29: =COUNTIFS(secondary_acts!$A$2:$A$771,$A29,secondary_acts!$E$2:$E$771,"delegated") -> 0 | AM29: =COUNTIFS(secondary_acts!$A$2:$A$771,$A29,secondary_acts!$E$2:$E$771,"other Commission/Council act") -> 0 | AN29: =COUNTIFS(secondary_acts!$A$2:$A$771,$A29,secondary_acts!$E$2:$E$771,"guidance") -> 0 | AO29: =COUNTIF(guidance_web!$A$2:$A$7,$A29) -> 0 | AP29: =COUNTIFS(guidance_agencies!$A$2:$A$81,$A29,guidance_agencies!$D$2:$D$81,"EDPB") -> 0 | AQ29: =COUNTIFS(guidance_agencies!$A$2:$A$81,$A29,guidance_agencies!$D$2:$D$81,"EBA") -> 0 | AR29: =COUNTIFS(guidance_agencies!$A$2:$A$81,$A29,guidance_agencies!$D$2:$D$81,"ESMA") -> 0 | AS29: =SUMIFS(secondary_acts!$S$2:$S$771,secondary_acts!$A$2:$A$771,$A29,secondary_acts!$E$2:$E$771,"implementing")+SUMIFS(secondary_acts!$S$2:$S$771,secondary_acts!$A$2:$A$771,$A29,secondary_acts!$E$2:$E$771,"delegated") -> 0 | AT29: 1291 | AU29: 27 | AV29: 1 | AW29: 2024-06-13 | AX29: 2024-06-13 | AY29: 3 | AZ29: 52015PC0635 | BA29: EUR-Lex HTML | BB29: 6775 | BC29: 30 | BD29: 13 | BE29: =IF(ISNUMBER(BB29),Q29-BB29,"") -> 7556 | BF29: =IF(AND(ISNUMBER(BB29),BB29>0),(Q29-BB29)/BB29,"") -> 1.1152768 | BG29: =IF(ISNUMBER(BC29),X29-BC29,"") -> 12 | BH29: =IF(AND(ISNUMBER(BC29),BC29>0),(X29-BC29)/BC29,"") -> 0.4 | BI29: =IF(ISNUMBER(BD29),AD29-BD29,"") -> -2
A30: 29 | B30: Company Law Directive | C30: Directive (EU) 2017/1132 | D30: Competition & Single Market | E30: enacted | F30: 2015-12-03 | G30: medium | H30: 2017-06-14 | I30: 2017-06-30 | J30: 2017-07-20 | K30: adopted | L30: adopted | M30: 32017L1132 | N30: Original act as published in the OJ | O30: https://eur-lex.europa.eu/legal-content/EN/TXT/?uri=CELEX:32017L1132 | P30: 82 | Q30: 39977 | R30: 5821 | S30: 5409 | T30: 32119 | U30: 2037 | V30: 0 | W30: 0 | X30: 436 | Y30: 314 | Z30: 78 | AA30: 16 | AB30: 8 | AC30: 20 | AD30: 116 | AE30: 132 | AF30: 22 | AG30: 166 | AH30: 02017L1132-20220812 | AI30: 777 | AJ30: 156 | AK30: =COUNTIFS(secondary_acts!$A$2:$A$771,$A30,secondary_acts!$E$2:$E$771,"implementing") -> 2 | AL30: =COUNTIFS(secondary_acts!$A$2:$A$771,$A30,secondary_acts!$E$2:$E$771,"delegated") -> 0 | AM30: =COUNTIFS(secondary_acts!$A$2:$A$771,$A30,secondary_acts!$E$2:$E$771,"other Commission/Council act") -> 0 | AN30: =COUNTIFS(secondary_acts!$A$2:$A$771,$A30,secondary_acts!$E$2:$E$771,"guidance") -> 0 | AO30: =COUNTIF(guidance_web!$A$2:$A$7,$A30) -> 0 | AP30: =COUNTIFS(guidance_agencies!$A$2:$A$81,$A30,guidance_agencies!$D$2:$D$81,"EDPB") -> 0 | AQ30: =COUNTIFS(guidance_agencies!$A$2:$A$81,$A30,guidance_agencies!$D$2:$D$81,"EBA") -> 0 | AR30: =COUNTIFS(guidance_agencies!$A$2:$A$81,$A30,guidance_agencies!$D$2:$D$81,"ESMA") -> 0 | AS30: =SUMIFS(secondary_acts!$S$2:$S$771,secondary_acts!$A$2:$A$771,$A30,secondary_acts!$E$2:$E$771,"implementing")+SUMIFS(secondary_acts!$S$2:$S$771,secondary_acts!$A$2:$A$771,$A30,secondary_acts!$E$2:$E$771,"delegated") -> 292 | AT30: 1440 | AU30: 10 | AV30: 6 | AW30: 2019-06-20 | AX30: 2024-12-19 | AY30: 3 | AZ30: 52015PC0616 | BA30: EUR-Lex HTML | BB30: 41520 | BC30: 471 | BD30: 123 | BE30: =IF(ISNUMBER(BB30),Q30-BB30,"") -> -1543 | BF30: =IF(AND(ISNUMBER(BB30),BB30>0),(Q30-BB30)/BB30,"") -> -0.037162813 | BG30: =IF(ISNUMBER(BC30),X30-BC30,"") -> -35 | BH30: =IF(AND(ISNUMBER(BC30),BC30>0),(X30-BC30)/BC30,"") -> -0.074309979 | BI30: =IF(ISNUMBER(BD30),AD30-BD30,"") -> -7
